// // 3 - Reescreva o teste do exercÃ­cio anterior, desta vez utilizando a sintaxe de async/await .
// Dica: Utilize o try/catch para o caso de erro.

const users = {
  4: { name: 'Mark' },
  5: { name: 'Paul' }
};
  
const findUserById = (id) => {
  return new Promise((resolve, reject) => {
      if (users[id]) {
        return resolve(users[id]);
      }
      return reject({ error: 'User with ' + id + ' not found.' });
  });
}

const getUserName = (userID) => {
  return findUserById(userID).then(user => user.name);
}

describe('getUserName - async/await', () => {
  describe('when the user id exists', () => {
    it('returns the user name', async () => {
      expect.assertions(1);
      const data = await getUserName(4);
      expect(data).toEqual('Mark');
    });
  });

  describe('when the user id does not exists', () => {
    it('returns an error', async () => {
      expect.assertions(1);
      try {
        await getUserName(1);
      } catch (error) {
        expect(error).toEqual({ error: 'User with 1 not found.' });
      }
    });
  });
});
