// Exemplo 1: Tratando erros de forma síncrona.
function dividirNumeros(num1, num2) {
  if (num2 == 0) throw new Error("Não pode ser feito uma divisão por zero");

  return num1 / num2;
}

try {
  const resultado = dividirNumeros(2, 1);
  console.log(`resultado: ${resultado}`);
} catch (e) {
  console.log(e.message);
}

// Exemplo 2: Tratando erros de forma assíncrona.
function dividirNumeros(num1, num2) {
  const promise = new Promise((resolve, reject) => {
    if (num2 == 0) reject(new Error("Não pode ser feito uma divisão por zero"));

    const resultado = num1 / num2;
    resolve(resultado)
  });

  return promise;
}

dividirNumeros(2, 1)
  .then(result => console.log(`sucesso: ${result}`))
  .catch(err => console.log(`erro: ${err.message}`));
